vespasian report -o ./vespasian_report7 ./vespasian_codeml7
Traceback (most recent call last):
  File "/usr/local/lib/python3.6/dist-packages/pandas/core/indexes/base.py", line 2897, in get_loc
    return self._engine.get_loc(key)
  File "pandas/_libs/index.pyx", line 107, in pandas._libs.index.IndexEngine.get_loc
  File "pandas/_libs/index.pyx", line 131, in pandas._libs.index.IndexEngine.get_loc
  File "pandas/_libs/hashtable_class_helper.pxi", line 1607, in pandas._libs.hashtable.PyObjectHashTable.get_item
  File "pandas/_libs/hashtable_class_helper.pxi", line 1614, in pandas._libs.hashtable.PyObjectHashTable.get_item
KeyError: 'beb_sites'

During handling of the above exception, another exception occurred:

Traceback (most recent call last):
  File "/usr/local/bin/vespasian", line 11, in <module>
    sys.exit(main())
  File "/usr/local/lib/python3.6/dist-packages/vespasian/cli.py", line 134, in main
    version])
  File "/usr/local/lib/python3.6/dist-packages/argh/dispatching.py", line 328, in dispatch_commands
    dispatch(parser, *args, **kwargs)
  File "/usr/local/lib/python3.6/dist-packages/argh/dispatching.py", line 174, in dispatch
    for line in lines:
  File "/usr/local/lib/python3.6/dist-packages/argh/dispatching.py", line 277, in _execute_command
    for line in result:
  File "/usr/local/lib/python3.6/dist-packages/argh/dispatching.py", line 260, in _call
    result = function(*positional, **keywords)
  File "/usr/local/lib/python3.6/dist-packages/vespasian/cli.py", line 51, in report
    vespasian.report(input, output)
  File "/usr/local/lib/python3.6/dist-packages/vespasian/vespasian.py", line 616, in report
    summary_df = summarise(family_results)
  File "/usr/local/lib/python3.6/dist-packages/vespasian/vespasian.py", line 539, in summarise
    df['beb_sites'] = df['beb_sites'].apply(fmt_sites)
  File "/usr/local/lib/python3.6/dist-packages/pandas/core/frame.py", line 2995, in __getitem__
    indexer = self.columns.get_loc(key)
  File "/usr/local/lib/python3.6/dist-packages/pandas/core/indexes/base.py", line 2899, in get_loc
    return self._engine.get_loc(self._maybe_cast_indexer(key))
  File "pandas/_libs/index.pyx", line 107, in pandas._libs.index.IndexEngine.get_loc
  File "pandas/_libs/index.pyx", line 131, in pandas._libs.index.IndexEngine.get_loc
  File "pandas/_libs/hashtable_class_helper.pxi", line 1607, in pandas._libs.hashtable.PyObjectHashTable.get_item
  File "pandas/_libs/hashtable_class_helper.pxi", line 1614, in pandas._libs.hashtable.PyObjectHashTable.get_item
KeyError: 'beb_sites'
